<?xml version="1.0" encoding="utf-8"?>
<!-- This URDF was automatically created by SolidWorks to URDF Exporter! Originally created by Stephen Brawner (brawner@gmail.com) 
     Commit Version: 1.6.0-4-g7f85cfe  Build Version: 1.6.7995.38578
     For more information, please see http://wiki.ros.org/sw_urdf_exporter -->
<robot
  name="nz">
  <link
    name="base_link">
    <inertial>
      <origin
        xyz="0.0769904470235003 0.00376622557167896 0.0685155092090075"
        rpy="0 0 0" />
      <mass
        value="3.14909562495719" />
      <inertia
        ixx="0.0115327530086724"
        ixy="-4.91965547412153E-05"
        ixz="-9.61237797897977E-06"
        iyy="0.00821991322309177"
        iyz="6.05426565289906E-06"
        izz="0.0164872754951684" />
    </inertial>
    <visual>
      <origin
        xyz="0 0 0"
        rpy="0 0 0" />
      <geometry>
        <mesh
          filename="../meshes/base_link.STL" />
      </geometry>
      <material
        name="">
        <color
          rgba="1 1 1 1" />
      </material>
    </visual>
    <collision>
      <origin
        xyz="0 0 0"
        rpy="0 0 0" />
      <geometry>
        <mesh
          filename="../meshes/base_link.STL" />
      </geometry>
    </collision>
  </link>
  <link
    name="left_hip_link">
    <inertial>
      <origin
        xyz="-0.129171227398525 0.0184514477555795 -7.71392966182108E-05"
        rpy="0 0 0" />
      <mass
        value="1.50729161316157" />
      <inertia
        ixx="0.00109165066776165"
        ixy="-1.75731665546427E-08"
        ixz="1.08189970559121E-05"
        iyy="0.0023999136725645"
        iyz="2.99999001996132E-08"
        izz="0.00167793200864633" />
    </inertial>
    <visual>
      <origin
        xyz="0 0 0"
        rpy="0 0 0" />
      <geometry>
        <mesh
          filename="../meshes/left_hip_link.STL" />
      </geometry>
      <material
        name="">
        <color
          rgba="0.792156862745098 0.819607843137255 0.933333333333333 1" />
      </material>
    </visual>
    <collision>
      <origin
        xyz="0 0 0"
        rpy="0 0 0" />
      <geometry>
        <mesh
          filename="../meshes/left_hip_link.STL" />
      </geometry>
    </collision>
  </link>
  <joint
    name="left_hip_joint"
    type="fixed">
    <origin
      xyz="0.15125 0.1033 0.074"
      rpy="3.1409 0 0" />
    <parent
      link="base_link" />
    <child
      link="left_hip_link" />
    <axis
      xyz="1 0 0" />
    <limit
      effort="23"
      velocity="0" />
  </joint>
  <link
    name="left_thigh_link">
    <inertial>
    <!-- bug -->
      <origin
        xyz="0.0938836587971054 0.0127372960179873 0.00955210764179379"
        rpy="0 0 0" />
      <mass
        value="0.123171535651979" />
      <inertia
        ixx="2.90954803852798E-05"
        ixy="-2.8455977977593E-06"
        ixz="7.11907178080081E-21"
        iyy="0.000329412370206532"
        iyz="-3.70876767395807E-21"
        izz="0.000357308613798386" />
    </inertial>
    <visual>
      <origin
        xyz="0 0 0"
        rpy="0 0 0" />
      <geometry>
        <mesh
          filename="../meshes/left_thigh_link.STL" />
      </geometry>
      <material
        name="">
        <color
          rgba="0.792156862745098 0.819607843137255 0.933333333333333 1" />
      </material>
    </visual>
    <collision>
      <origin
        xyz="0 0 0"
        rpy="0 0 0" />
      <geometry>
        <mesh
          filename="../meshes/left_thigh_link.STL" />
      </geometry>
    </collision>
  </link>
  <joint
    name="left_thigh_joint"
    type="continuous">
    <origin
      xyz="-0.176 -0.0303 0"
      rpy="-1.5708 -0.68019 3.1416" />
      <!-- bug -->
    <parent
      link="left_hip_link" />
    <child
      link="left_thigh_link" />
    <axis
      xyz="0 0 1" />
    <limit
      effort="30"
      velocity="0" />
  </joint>
  <link
    name="left_calf_link">
    <inertial>
      <origin
        xyz="0.136720753643137 -7.49630519447653E-06 0.00583906008359109"
        rpy="0 0 0" />
      <mass
        value="0.347648896809242" />
        <!-- bug -->
      <inertia
        ixx="0.00011843459236735"
        ixy="-4.25398708963913E-08"
        ixz="3.79249344943144E-08"
        iyy="0.000821285413475793"
        iyz="-4.42816346601129E-08"
        izz="0.000925309688557115" />
    </inertial>
    <visual>
      <origin
        xyz="0 0 0"
        rpy="0 0 0" />
      <geometry>
        <mesh
          filename="../meshes/left_calf_link.STL" />
      </geometry>
      <material
        name="">
        <color
          rgba="0.792156862745098 0.819607843137255 0.933333333333333 1" />
      </material>
    </visual>
    <collision>
      <origin
        xyz="0 0 0"
        rpy="0 0 0" />
      <geometry>
        <mesh
          filename="../meshes/left_calf_link.STL" />
      </geometry>
    </collision>
  </link>
  <joint
    name="left_calf_joint"
    type="continuous">
    <origin
      xyz="0.18 0 0.018"
      rpy="0 0 -2.0318" />
    <parent
      link="left_thigh_link" />
    <child
      link="left_calf_link" />
    <axis
      xyz="0 0 1" />
    <limit
      effort="30"
      velocity="0" />
  </joint>
  <link
    name="left_wheel_link">
    <inertial>
      <origin
        xyz="1.47725165433599E-11 -2.95270197181452E-11 0.0134999704617803"
        rpy="0 0 0" />
      <mass
        value="0.440514867448167" />
      <inertia
        ixx="0.000891368440948039"
        ixy="-7.73935303760884E-12"
        ixz="1.19810512251009E-13"
        iyy="0.000891368447482818"
        iyz="-2.39418501479716E-13"
        izz="0.00165284876799871" />
    </inertial>
    <visual>
      <origin
        xyz="0 0 0"
        rpy="0 0 0" />
      <geometry>
        <mesh
          filename="../meshes/left_wheel_link.STL" />
      </geometry>
      <material
        name="">
        <color
          rgba="0.376470588235294 0.376470588235294 0.376470588235294 1" />
      </material>
    </visual>
    <collision>
      <origin
        xyz="0 0 0"
        rpy="0 0 0" />
      <geometry>
        <mesh
          filename="../meshes/left_wheel_link.STL" />
      </geometry>
    </collision>
  </link>
  <joint
    name="left_wheel_joint"
    type="continuous">
    <origin
      xyz="0.216 0 0.027"
      rpy="0 0 -2.0004" />
    <parent
      link="left_calf_link" />
    <child
      link="left_wheel_link" />
    <axis
      xyz="0 0 1" />
    <limit
      effort="12"
      velocity="0" />
  </joint>
  <link
    name="right_hip_link">
    <inertial>
      <origin
        xyz="-0.128385294753452 -0.0182878272673425 -0.00108343495269913"
        rpy="0 0 0" />
      <mass
        value="1.50805982681315" />
      <inertia
        ixx="0.00109167194621112"
        ixy="-1.75736759545931E-08"
        ixz="1.06840929047845E-05"
        iyy="0.00239992505054775"
        iyz="-3.54971507087337E-08"
        izz="0.00167794054575014" />
    </inertial>
    <visual>
      <origin
        xyz="0 0 0"
        rpy="0 0 0" />
      <geometry>
        <mesh
          filename="../meshes/right_hip_link.STL" />
      </geometry>
      <material
        name="">
        <color
          rgba="0.792156862745098 0.819607843137255 0.933333333333333 1" />
      </material>
    </visual>
    <collision>
      <origin
        xyz="0 0 0"
        rpy="0 0 0" />
      <geometry>
        <mesh
          filename="../meshes/right_hip_link.STL" />
      </geometry>
    </collision>
  </link>
  <joint
    name="right_hip_joint"
    type="fixed">
    <origin
      xyz="0.151248020480631 -0.0966979671516186 0.0741460709475268"
      rpy="3.14086625012173 0 0" />
    <parent
      link="base_link" />
    <child
      link="right_hip_link" />
    <axis
      xyz="1 0 0" />
    <limit
      effort="23"
      velocity="0" />
  </joint>
  <link
    name="right_thigh_Link">
    <inertial>
      <origin
        xyz="0.0938836587971048 0.0127372960179877 -0.00954138692712792"
        rpy="0 0 0" />
      <mass
        value="0.123171535651979" />
      <inertia
        ixx="2.90954803852799E-05"
        ixy="-2.84559779775897E-06"
        ixz="1.15115494674737E-20"
        iyy="0.000329412370206532"
        iyz="2.97412789243441E-21"
        izz="0.000357308613798386" />
    </inertial>
    <visual>
      <origin
        xyz="0 0 0"
        rpy="0 0 0" />
      <geometry>
        <mesh
          filename="../meshes/right_thigh_Link.STL" />
      </geometry>
      <material
        name="">
        <color
          rgba="0.792156862745098 0.819607843137255 0.933333333333333 1" />
      </material>
    </visual>
    <collision>
      <origin
        xyz="0 0 0"
        rpy="0 0 0" />
      <geometry>
        <mesh
          filename="../meshes/right_thigh_Link.STL" />
      </geometry>
    </collision>
  </link>
  <joint
    name="right_thigh_joint"
    type="continuous">
    <origin
      xyz="-0.176 0.0302519795191535 0"
      rpy="-1.57079146990323 -0.680186568657904 3.14158959890566" />
    <parent
      link="right_hip_link" />
    <child
      link="right_thigh_Link" />
    <axis
      xyz="0 0 1" />
    <limit
      effort="30"
      velocity="0" />
  </joint>
  <link
    name="right_calf_Link">
    <inertial>
      <origin
        xyz="0.136704678264452 1.77271490062192E-06 0.00583499141755464"
        rpy="0 0 0" />
      <mass
        value="0.34764888954821" />
      <inertia
        ixx="0.000118519607830654"
        ixy="6.66951864775324E-09"
        ixz="6.89040903925435E-08"
        iyy="0.000821200378218265"
        iyz="9.44946416323169E-09"
        izz="0.000925309669054206" />
    </inertial>
    <visual>
      <origin
        xyz="0 0 0"
        rpy="0 0 0" />
      <geometry>
        <mesh
          filename="../meshes/right_calf_Link.STL" />
      </geometry>
      <material
        name="">
        <color
          rgba="0.792156862745098 0.819607843137255 0.933333333333333 1" />
      </material>
    </visual>
    <collision>
      <origin
        xyz="0 0 0"
        rpy="0 0 0" />
      <geometry>
        <mesh
          filename="../meshes/right_calf_Link.STL" />
      </geometry>
    </collision>
  </link>
  <joint
    name="right_calf_joint"
    type="continuous">
    <origin
      xyz="0.180000000000001 0 -0.0179999999999999"
      rpy="3.14159265358979 0 -2.03182056503967" />
    <parent
      link="right_thigh_Link" />
    <child
      link="right_calf_Link" />
    <axis
      xyz="0 0 1" />
    <limit
      effort="30"
      velocity="0" />
  </joint>
  <link
    name="right_wheel_Link">
    <inertial>
      <origin
        xyz="1.96671012808736E-11 2.65185096104403E-11 0.0134999704617851"
        rpy="0 0 0" />
      <mass
        value="0.440514867448074" />
      <inertia
        ixx="0.000891368439909627"
        ixy="7.21350543689662E-12"
        ixz="1.59455352702864E-13"
        iyy="0.000891368448520965"
        iyz="2.15057902111473E-13"
        izz="0.00165284876799856" />
    </inertial>
    <visual>
      <origin
        xyz="0 0 0"
        rpy="0 0 0" />
      <geometry>
        <mesh
          filename="../meshes/right_wheel_Link.STL" />
      </geometry>
      <material
        name="">
        <color
          rgba="0.376470588235294 0.376470588235294 0.376470588235294 1" />
      </material>
    </visual>
    <collision>
      <origin
        xyz="0 0 0"
        rpy="0 0 0" />
      <geometry>
        <mesh
          filename="../meshes/right_wheel_Link.STL" />
      </geometry>
    </collision>
  </link>
  <joint
    name="right_wheel_joint"
    type="continuous">
    <origin
      xyz="0.216000000000001 0 0.027"
      rpy="0 0 -1.14121080690845" />
    <parent
      link="right_calf_Link" />
    <child
      link="right_wheel_Link" />
    <axis
      xyz="0 0 1" />
    <limit
      effort="12"
      velocity="0" />
  </joint>
</robot>