<mujoco model="nz2">
  <compiler angle="radian" />
  <option integrator="RK4" timestep="0.002" />
  <asset>
    <mesh name="base_link" file="base_link.STL" />
    <mesh name="left_hip_link" file="left_hip_link.STL" />
    <mesh name="left_thigh_link" file="left_thigh_link.STL" />
    <mesh name="left_calf_link" file="left_calf_link.STL" />
    <mesh name="left_wheel_link" file="left_wheel_link.STL" />
    <mesh name="right_hip_link" file="right_hip_link.STL" />
    <mesh name="right_thigh_Link" file="right_thigh_Link.STL" />
    <mesh name="right_calf_Link" file="right_calf_Link.STL" />
    <mesh name="right_wheel_Link" file="right_wheel_Link.STL" />
  </asset>

  <default>
    <default class="visual">
      <!-- <geom contype="0" conaffinity="0" group="2"/> -->
    </default>
    <default class="hip">
      <geom contype="2" conaffinity="2" />
    </default>
    <default class="thigh">
      <geom contype="4" conaffinity="4" />
    </default>
    <default class="wheel">
      <geom contype="1" conaffinity="1" />
    </default>
  </default>

  <worldbody>
    <body name="nz" pos="0 0 0.15">
      <freejoint/>
      <site name="imu"/>
      <geom type="mesh" rgba="1 1 1 1" mesh="base_link" />
      <geom pos="0.15125 0.1033 0.074" quat="0.000346327 1 0 0" type="mesh"
        rgba="0.792157 0.819608 0.933333 1" mesh="left_hip_link" class="hip"/>
      <geom pos="0.15125 -0.096698 0.074146" quat="0.000346327 1 0 0" type="mesh"
        rgba="0.792157 0.819608 0.933333 1" mesh="right_hip_link" class="hip"/>
      <body name="left_thigh_link" pos="-0.02475 0.133601 0.073979"
        quat="-0.185794 0.185918 -0.68248 -0.682009">
        <inertial pos="0.0975304 0.0101391 0.00955211"
          quat="-0.00413675 0.707095 0.00413675 0.707095"
          mass="0.123172" diaginertia="0.000357309 0.000331531 2.69773e-05" />
        <joint name="left_thigh_joint" pos="0 0 0" axis="0 0 1" range="-1.0472 0.5236"
          actuatorfrcrange="-40 40" damping="0.5"/>
        <geom type="mesh" rgba="0.792157 0.819608 0.933333 1" mesh="left_thigh_link" class="thigh"/>
        <body name="left_calf_link" pos="0.18 0 0.018" quat="0.386512 0 0 -0.922285">
          <inertial pos="0.136721 -5.95712e-06 0.00583906"
            quat="-0.000161277 0.707127 -0.000109089 0.707087" mass="0.347649"
            diaginertia="0.00092531 0.000821271 0.000118449" />
          <joint name="left_calf_joint" pos="0 0 0" axis="0 0 1" range="0 1.3963"
            actuatorfrcrange="-40 40" damping="0.5"/>
          <geom type="mesh" rgba="0.792157 0.819608 0.933333 1" mesh="left_calf_link" />
          <body name="left_wheel_link" pos="0.216 0 0.027" quat="0.60876 0 0 -0.793355">
            <inertial pos="1.47719e-11 -2.95262e-11 0.0135"
              quat="-0.204115 0.677006 0.204115 0.677006" mass="0.440515"
              diaginertia="0.00165285 0.000891368 0.000891368" />
            <joint name="left_wheel_joint" pos="0 0 0" axis="0 0 1" actuatorfrcrange="-40 40" damping="0.5"/>
            <geom type="mesh" rgba="0.376471 0.376471 0.376471 1" mesh="left_wheel_link" />
          </body>
        </body>
      </body>
      <body name="right_thigh_Link" pos="-0.02475 -0.126949 0.074167"
        quat="-0.185794 0.185918 -0.68248 -0.682009">
        <inertial pos="0.0975304 0.0101391 -0.00954139"
          quat="-0.00413675 0.707095 0.00413675 0.707095" mass="0.123172"
          diaginertia="0.000357309 0.000331531 2.69773e-05" />
        <joint name="right_thigh_joint" pos="0 0 0" axis="0 0 1" range="-1.0472 0.5236"
          actuatorfrcrange="-40 40" damping="0.5"/>
        <geom type="mesh" rgba="0.792157 0.819608 0.933333 1" mesh="right_thigh_Link" class="thigh"/>
        <body name="right_calf_Link" pos="0.18 0 -0.018" quat="0.386512 0 0 -0.922285">
          <inertial pos="0.136706 -2.87389e-06 -0.00583499"
            quat="6.61143e-06 0.707077 -3.95609e-06 0.707137" mass="0.347649"
            diaginertia="0.00092531 0.000821199 0.000118521" />
          <joint name="right_calf_joint" pos="0 0 0" axis="0 0 1" range="0 1.3963"
            actuatorfrcrange="-40 40" damping="0.5"/>
          <geom type="mesh" rgba="0.792157 0.819608 0.933333 1" mesh="right_calf_Link" />
          <body name="right_wheel_Link" pos="0.216 0 -0.027" quat="0.60876 0 0 -0.793355">
            <inertial pos="0 3.30142e-11 -0.0135" quat="0.0398998 0.70598 -0.0398998 0.70598"
              mass="0.440515" diaginertia="0.00165285 0.000891368 0.000891368" />
            <joint name="right_wheel_joint" pos="0 0 0" axis="0 0 1" actuatorfrcrange="-40 40" damping="0.5"/>
            <geom type="mesh" rgba="0.376471 0.376471 0.376471 1" mesh="right_wheel_Link" />
          </body>
        </body>
      </body>
    </body>
  </worldbody>

  <actuator>
    <!-- <position joint="left_hip_joint" name="left_hip_joint" kp="80" kv="2" ctrlrange="-0.31416 0.31416"/> -->
    <position joint="left_thigh_joint" name="left_thigh_joint" kp="80" kv="2" ctrlrange="-0.785399 0.785399" forcerange="-40 40"/>
    <position joint="left_calf_joint" name="left_calf_joint" kp="30" kv="1.2" ctrlrange="0 1.3963" forcerange="-40 40"/>
    <!-- <position joint="right_hip_joint" name="right_hip_joint" kp="30" kv="1.2" ctrlrange="-0.31416 0.31416"/> -->
    <position joint="right_thigh_joint" name="right_thigh_joint" kp="30" kv="1.2" ctrlrange="-0.785399 0.785399" forcerange="-40 40"/>
    <position joint="right_calf_joint" name="right_calf_joint" kp="30" kv="1.2" ctrlrange="0 1.3963" forcerange="-40 40"/>
    <intvelocity joint="left_wheel_joint" name="left_wheel_joint" kp="30" kv="1.2"  forcerange="-40 40" actrange="-100 100"/>
    <intvelocity joint="right_wheel_joint" name="right_wheel_joint" kp="30" kv="1.2"  forcerange="-40 40" actrange="-100 100"/>
  </actuator>

  <sensor>
    <jointpos name='left_thigh_joint_p' joint='left_thigh_joint' />
    <jointpos name='left_calf_joint_p' joint='left_calf_joint' />
    <jointpos name='right_thigh_joint_p' joint='right_thigh_joint' />
    <jointpos name='right_calf_joint_p' joint='right_calf_joint' />
    <jointpos name='left_wheel_joint_p' joint='left_wheel_joint' />
    <jointpos name='right_wheel_joint_p' joint='right_wheel_joint' />

    <jointvel name='left_thigh_joint_v' joint='left_thigh_joint' />
    <jointvel name='left_calf_joint_v' joint='left_calf_joint' />
    <jointvel name='right_thigh_joint_v' joint='right_thigh_joint' />
    <jointvel name='right_calf_joint_v' joint='right_calf_joint' />
    <jointvel name='left_wheel_joint_v' joint='left_wheel_joint' />
    <jointvel name='right_wheel_joint_v' joint='right_wheel_joint' />

    <framequat name='orientation' objtype='body' objname='nz' />
    <framelinvel name="base_lin_vel" objtype="body" objname="nz" />
    <gyro name='base_ang_vel' site='imu' />
    <framepos name='base_pos' objtype='body' objname='nz' />
    <!-- <accelerometer name="projected_gravity" site="imu" /> -->
  </sensor>

</mujoco>