<mujoco model="nz">
  <compiler angle="radian" />
  <!-- integrator="RK4"  -->
  <option timestep="0.01" />
  <asset>
    <mesh name="base_link" file="base_link.STL" />
    <mesh name="left_hip_link" file="left_hip_link.STL" />
    <mesh name="left_thigh_link" file="left_thigh_link.STL" />
    <mesh name="left_calf_link" file="left_calf_link.STL" />
    <mesh name="left_wheel_link" file="left_wheel_link.STL" />
    <mesh name="left_knee_link" file="left_knee_link.STL" />
    <mesh name="right_hip_link" file="right_hip_link.STL" />
    <mesh name="right_thigh_link" file="right_thigh_link.STL" />
    <mesh name="right_calf_link" file="right_calf_link.STL" />
    <mesh name="right_knee_link" file="right_knee_link.STL" />
    <mesh name="right_wheel_link" file="right_wheel_link.STL" />
  </asset>

  <worldbody>
    <body name="urdf2nz" pos="0 0 0.0">
    <inertial pos="0 0 0" quat="1 0 0 0" mass="4.1216284" diaginertia="0.001 0.001 0.001"/>  
      <freejoint/>
      <site name="imu"/>
      <geom type="mesh" rgba="0.79216 0.81961 0.93333 1" mesh="base_link" />
      <geom pos="0.151248 0.103302 0.074" quat="1 -0.00036509 0 0" type="mesh"
        rgba="0.79216 0.81961 0.93333 1" mesh="left_hip_link" contype="2" conaffinity="2" />
      <geom pos="0.15125 -0.096698 0.074146" quat="1 -0.00036509 0 0" type="mesh"
        rgba="0.79608 0.82353 0.93725 1" mesh="right_hip_link" contype="2" conaffinity="2" />
      <body name="left_thigh_link" pos="-0.024752 0.133603 0.0739779" quat="1 -0.00036509 0 0">
        <inertial pos="-0.087416 0.0096982 -0.040304" quat="0.650563 0.325254 0.355526 0.587008"
          mass="0.414174" diaginertia="0.00188395 0.00171179 0.000190252" />
        <joint name="left_thigh_joint" pos="0 0 0" axis="0 1 0" range="-1.0472 0.5236"
           damping="3"/>
        <geom type="mesh" rgba="0.79216 0.81961 0.93333 1" mesh="left_thigh_link" contype="4"
          conaffinity="4" />
        <body name="left_calf_link" pos="-0.15513 0.018 -0.091296">
          <inertial pos="0.16974 0.0023241 -0.045475" quat="0.370864 0.674273 0.264964 0.581042"
            mass="0.6553" diaginertia="0.00913562 0.00873571 0.000669561" />
          <joint name="left_calf_joint" pos="0 0 0" axis="0 1 0" range="0 1.3963"
             damping="3"/>
          <geom type="mesh" rgba="0.79216 0.81961 0.93333 1" mesh="left_calf_link" />
          <body name="left_wheel_link" pos="0.20864 0.027 -0.055905">
            <inertial pos="-2.9526e-11 0.0135 1.4772e-11"
              quat="0.707107 -0.000245428 0.000245428 0.707107" mass="0.75"
              diaginertia="0.0028141 0.0015176 0.0015176" />
            <joint name="left_wheel_joint" pos="0 0 0" axis="0 1 0"  damping="3"/>
            <geom type="mesh" rgba="0.37647 0.37647 0.37647 1" mesh="left_wheel_link" />
          </body>
          <body name="left_knee_link" pos="-0.048296 0.02265 0.012941">
            <inertial pos="5.4459e-05 1.1771e-05 -5.6171e-06"
              quat="0.26945 0.656041 0.65051 0.271741"
              mass="0.09" diaginertia="4.36012e-05 2.68988e-05 2.67e-05" />
            <joint name="left_knee_wheel_joint" pos="0 0 0" axis="0 1 0"  damping="3"/>
            <geom type="mesh" rgba="1 1 1 1" mesh="left_knee_link" />
          </body>
        </body>
      </body>
      <body name="right_thigh_link" pos="-0.02475 -0.126949 0.0741681" quat="1 -0.00036509 0 0">
        <inertial pos="-0.090239 -0.0063515 -0.041235" quat="0.541253 0.401142 0.350968 0.650347"
          mass="0.263997" diaginertia="0.00110561 0.000994534 0.000117851" />
        <joint name="right_thigh_joint" pos="0 0 0" axis="0 1 0" range="-1.0472 0.5236"
           damping="3"/>
        <geom type="mesh" rgba="0.79216 0.81961 0.93333 1" mesh="right_thigh_link" contype="4"
          conaffinity="4" />
        <body name="right_calf_link" pos="-0.15513 -0.018001 -0.091296">
          <inertial pos="0.16973 -0.0023235 -0.045486" quat="0.160073 0.735833 0.426682 0.500868"
            mass="0.6553" diaginertia="0.00913554 0.00873578 0.000669482" />
          <joint name="right_calf_joint" pos="0 0 0" axis="0 1 0" range="0 1.3963"
             damping="3"/>
          <geom type="mesh" rgba="0.79216 0.81961 0.93333 1" mesh="right_calf_link" />
          <body name="right_knee_link" pos="-0.0482963 -0.02265 0.012941">
            <inertial pos="-2.2425e-05 1.2382e-05 5.0075e-05"
              quat="0.691119 0.139081 0.13578 0.696114" mass="0.09"
              diaginertia="4.36012e-05 2.69404e-05 2.66584e-05" />
            <joint name="right_knee_wheel_joint" pos="0 0 0" axis="0 1 0" damping="0.0005"/>
            <geom type="mesh" rgba="1 1 1 1" mesh="right_knee_link" />
          </body>
          <body name="right_wheel_link" pos="0.20864 -0.026999 -0.055905">
            <inertial pos="3.3014e-11 -0.0135 0" quat="0.707107 -0.000245428 0.000245428 0.707107"
              mass="0.75" diaginertia="0.0028141 0.0015176 0.0015176" />
            <joint name="right_wheel_joint" pos="0 0 0" axis="0 1 0" actuatorfrcrange="-12 12" damping="0.0005"/>
            <geom type="mesh" rgba="0.37647 0.37647 0.37647 1" mesh="right_wheel_link" />
          </body>
        </body>
      </body>
    </body>
  </worldbody>

  <actuator>
    <!-- <position joint="left_hip_joint" name="left_hip_joint" kp="80" kv="2" ctrlrange="-0.31416 0.31416"/> -->
    <position joint="left_thigh_joint" name="left_thigh_joint" kp="30" kv="1.2" ctrlrange="-0.785399 0.785399" forcerange="-40 40"/>
    <position joint="left_calf_joint" name="left_calf_joint" kp="30" kv="1.2" ctrlrange="0 1.3963" forcerange="-40 40"/>
    <!-- <position joint="right_hip_joint" name="right_hip_joint" kp="30" kv="1.2" ctrlrange="-0.31416 0.31416"/> -->
    <position joint="right_thigh_joint" name="right_thigh_joint" kp="30" kv="1.2" ctrlrange="-0.785399 0.785399" forcerange="-40 40"/>
    <position joint="right_calf_joint" name="right_calf_joint" kp="30" kv="1.2" ctrlrange="0 1.3963" forcerange="-40 40"/>
    <intvelocity joint="left_wheel_joint" name="left_wheel_joint" kp="30" kv="1.2"  forcerange="-40 40" actrange="-100 100"/>
    <intvelocity joint="right_wheel_joint" name="right_wheel_joint" kp="30" kv="1.2"  forcerange="-40 40" actrange="-100 100"/>
  </actuator>

  <sensor>
    <jointpos name='left_thigh_joint_p' joint='left_thigh_joint' />
    <jointpos name='left_calf_joint_p' joint='left_calf_joint' />
    <jointpos name='right_thigh_joint_p' joint='right_thigh_joint' />
    <jointpos name='right_calf_joint_p' joint='right_calf_joint' />
    <jointpos name='left_wheel_joint_p' joint='left_wheel_joint' />
    <jointpos name='right_wheel_joint_p' joint='right_wheel_joint' />

    <jointvel name='left_thigh_joint_v' joint='left_thigh_joint' />
    <jointvel name='left_calf_joint_v' joint='left_calf_joint' />
    <jointvel name='right_thigh_joint_v' joint='right_thigh_joint' />
    <jointvel name='right_calf_joint_v' joint='right_calf_joint' />
    <jointvel name='left_wheel_joint_v' joint='left_wheel_joint' />
    <jointvel name='right_wheel_joint_v' joint='right_wheel_joint' />

    <framequat name='orientation' objtype='body' objname='urdf2nz' />
    <framelinvel name="base_lin_vel" objtype="body" objname="urdf2nz" />
    <gyro name='base_ang_vel' site='imu' />
    <framepos name='base_pos' objtype='body' objname='urdf2nz' />
    <!-- <accelerometer name="projected_gravity" site="imu" /> -->
  </sensor>
  
</mujoco>