<?xml version="1.0" encoding="utf-8"?>
<!-- This URDF was automatically created by SolidWorks to URDF Exporter! Originally created by Stephen Brawner (brawner@gmail.com) 
     Commit Version: 1.6.0-4-g7f85cfe  Build Version: 1.6.7995.38578
     For more information, please see http://wiki.ros.org/sw_urdf_exporter -->
<robot
  name="nz">
  <link
    name="base_link">
    <inertial>
      <origin
        xyz="0.0769904470232235 0.00376683911070541 0.0685156505120264"
        rpy="0 0 0" />
      <mass
        value="3.14909562497436" />
      <inertia
        ixx="0.0115327530086452"
        ixy="-4.91965547402417E-05"
        ixz="-9.61237799115126E-06"
        iyy="0.00821991322309608"
        iyz="6.05426566438534E-06"
        izz="0.0164872754951402" />
    </inertial>
    <visual>
      <origin
        xyz="0 0 0"
        rpy="0 0 0" />
      <geometry>
        <mesh
          filename="package://nz/meshes/base_link.STL" />
      </geometry>
      <material
        name="">
        <color
          rgba="1 1 1 1" />
      </material>
    </visual>
    <collision>
      <origin
        xyz="0 0 0"
        rpy="0 0 0" />
      <geometry>
        <mesh
          filename="package://nz/meshes/base_link.STL" />
      </geometry>
    </collision>
  </link>
  <link
    name="left_hip_link">
    <inertial>
      <origin
        xyz="-0.129171227398524 0.018450834317784 -7.72810454306034E-05"
        rpy="0 0 0" />
      <mass
        value="1.50729161316157" />
      <inertia
        ixx="0.00109165066776165"
        ixy="-1.75731665548429E-08"
        ixz="1.08189970559136E-05"
        iyy="0.0023999136725645"
        iyz="2.99999002205891E-08"
        izz="0.00167793200864633" />
    </inertial>
    <visual>
      <origin
        xyz="0 0 0"
        rpy="0 0 0" />
      <geometry>
        <mesh
          filename="package://nz/meshes/left_hip_link.STL" />
      </geometry>
      <material
        name="">
        <color
          rgba="0.792156862745098 0.819607843137255 0.933333333333333 1" />
      </material>
    </visual>
    <collision>
      <origin
        xyz="0 0 0"
        rpy="0 0 0" />
      <geometry>
        <mesh
          filename="package://nz/meshes/left_hip_link.STL" />
      </geometry>
    </collision>
  </link>
  <joint
    name="left_hip_joint"
    type="fixed">
    <origin
      xyz="0.15125 0.1033 0.074"
      rpy="3.1409 0 0" />
    <parent
      link="base_link" />
    <child
      link="left_hip_link" />
    <axis
      xyz="1 0 0" />
    <limit
      lower="-0.31416"
      upper="0.31416"
      effort="23.6"
      velocity="0" />
  </joint>
  <link
    name="left_thigh_link">
    <inertial>
      <origin
        xyz="0.09753 0.010139 0.0095521"
        rpy="0 0 0" />
      <mass
        value="0.12317" />
      <inertia
        ixx="2.7019E-05"
        ixy="-3.5631E-06"
        ixz="-9.6759E-21"
        iyy="0.00033149"
        iyz="4.5028E-20"
        izz="0.00035731" />
    </inertial>
    <visual>
      <origin
        xyz="0 0 0"
        rpy="0 0 0" />
      <geometry>
        <mesh
          filename="package://nz/meshes/left_thigh_link.STL" />
      </geometry>
      <material
        name="">
        <color
          rgba="0.79216 0.81961 0.93333 1" />
      </material>
    </visual>
    <collision>
      <origin
        xyz="0 0 0"
        rpy="0 0 0" />
      <geometry>
        <mesh
          filename="package://nz/meshes/left_thigh_link.STL" />
      </geometry>
    </collision>
  </link>
  <joint
    name="left_thigh_joint"
    type="continuous">
    <origin
      xyz="-0.176 -0.030301 0"
      rpy="-1.5708 -0.79373 3.1416" />
    <parent
      link="left_hip_link" />
    <child
      link="left_thigh_link" />
    <axis
      xyz="0 0 1" />
    <limit
      lower="-0.785399"
      upper="0.785399"
      effort="40"
      velocity="0" />
  </joint>
  <link
    name="left_calf_link">
    <inertial>
      <origin
        xyz="0.136721204889869 -3.48807778283167E-06 0.00583905980652485"
        rpy="0 0 0" />
      <mass
        value="0.347648899511391" />
      <inertia
        ixx="0.000118475406932545"
        ixy="-5.57176725483088E-08"
        ixz="5.62446640144163E-08"
        iyy="0.000821244598919594"
        iyz="-3.03119653882486E-08"
        izz="0.000925309688556767" />
    </inertial>
    <visual>
      <origin
        xyz="0 0 0"
        rpy="0 0 0" />
      <geometry>
        <mesh
          filename="package://nz/meshes/left_calf_link.STL" />
      </geometry>
      <material
        name="">
        <color
          rgba="0.792156862745098 0.819607843137255 0.933333333333333 1" />
      </material>
    </visual>
    <collision>
      <origin
        xyz="0 0 0"
        rpy="0 0 0" />
      <geometry>
        <mesh
          filename="package://nz/meshes/left_calf_link.STL" />
      </geometry>
    </collision>
  </link>
  <joint
    name="left_calf_joint"
    type="continuous">
    <origin
      xyz="0.18 0 0.018"
      rpy="0 0 -2.3479" />
    <parent
      link="left_thigh_link" />
    <child
      link="left_calf_link" />
    <axis
      xyz="0 0 1" />
    <limit
      lower="0"
      upper="1.3963"
      effort="40"
      velocity="0" />
  </joint>
  <link
    name="left_wheel_link">
    <inertial>
      <origin
        xyz="1.4771E-11 -2.9526E-11 0.0135"
        rpy="0 0 0" />
      <mass
        value="0.44051" />
      <inertia
        ixx="0.00089137"
        ixy="-7.7394E-12"
        ixz="1.1981E-13"
        iyy="0.00089137"
        iyz="-2.3942E-13"
        izz="0.0016528" />
    </inertial>
    <visual>
      <origin
        xyz="0 0 0"
        rpy="0 0 0" />
      <geometry>
        <mesh
          filename="package://nz/meshes/left_wheel_link.STL" />
      </geometry>
      <material
        name="">
        <color
          rgba="0.37647 0.37647 0.37647 1" />
      </material>
    </visual>
    <collision>
      <origin
        xyz="0 0 0"
        rpy="0 0 0" />
      <geometry>
        <mesh
          filename="package://nz/meshes/left_wheel_link.STL" />
      </geometry>
    </collision>
  </link>
  <joint
    name="left_wheel_joint"
    type="continuous">
    <origin
      xyz="0.216 0 0.027"
      rpy="0 0 -1.5708" />
    <parent
      link="left_calf_link" />
    <child
      link="left_wheel_link" />
    <axis
      xyz="0 0 1" />
    <limit
      effort="12"
      velocity="0" />
  </joint>
  <link
    name="right_hip_link">
    <inertial>
      <origin
        xyz="-0.128385294753452 -0.0182884407051373 -0.00108357670168383"
        rpy="0 0 0" />
      <mass
        value="1.50805982681315" />
      <inertia
        ixx="0.00109167194621112"
        ixy="-1.75736759548829E-08"
        ixz="1.06840929047845E-05"
        iyy="0.00239992505054775"
        iyz="-3.5497150687664E-08"
        izz="0.00167794054575013" />
    </inertial>
    <visual>
      <origin
        xyz="0 0 0"
        rpy="0 0 0" />
      <geometry>
        <mesh
          filename="package://nz/meshes/right_hip_link.STL" />
      </geometry>
      <material
        name="">
        <color
          rgba="0.792156862745098 0.819607843137255 0.933333333333333 1" />
      </material>
    </visual>
    <collision>
      <origin
        xyz="0 0 0"
        rpy="0 0 0" />
      <geometry>
        <mesh
          filename="package://nz/meshes/right_hip_link.STL" />
      </geometry>
    </collision>
  </link>
  <joint
    name="right_hip_joint"
    type="fixed">
    <origin
      xyz="0.15125 -0.096698 0.074146"
      rpy="3.1409 0 0" />
    <parent
      link="base_link" />
    <child
      link="right_hip_link" />
    <axis
      xyz="1 0 0" />
    <limit
      lower="-0.31416"
      upper="0.31416"
      effort="23.6"
      velocity="0" />
  </joint>
  <link
    name="right_thigh_Link">
    <inertial>
      <origin
        xyz="0.0975303738186116 0.0101391301476504 -0.00954138692712753"
        rpy="0 0 0" />
      <mass
        value="0.123171535651979" />
      <inertia
        ixx="2.70190359910818E-05"
        ixy="-3.56311870941751E-06"
        ixz="-1.80317360224376E-19"
        iyy="0.000331488814600731"
        iyz="5.224922528343E-20"
        izz="0.000357308613798386" />
    </inertial>
    <visual>
      <origin
        xyz="0 0 0"
        rpy="0 0 0" />
      <geometry>
        <mesh
          filename="package://nz/meshes/right_thigh_Link.STL" />
      </geometry>
      <material
        name="">
        <color
          rgba="0.792156862745098 0.819607843137255 0.933333333333333 1" />
      </material>
    </visual>
    <collision>
      <origin
        xyz="0 0 0"
        rpy="0 0 0" />
      <geometry>
        <mesh
          filename="package://nz/meshes/right_thigh_Link.STL" />
      </geometry>
    </collision>
  </link>
  <joint
    name="right_thigh_joint"
    type="continuous">
    <origin
      xyz="-0.176 0.030251 0"
      rpy="-1.5708 -0.79373 3.1416" />
    <parent
      link="right_hip_link" />
    <child
      link="right_thigh_Link" />
    <axis
      xyz="0 0 1" />
    <limit
      lower="-0.785399"
      upper="0.785399"
      effort="40"
      velocity="0" />
  </joint>
  <link
    name="right_calf_Link">
    <inertial>
      <origin
        xyz="0.13671 -4.171E-06 -0.005835"
        rpy="0 0 0" />
      <mass
        value="0.34765" />
      <inertia
        ixx="0.00011851"
        ixy="3.5278E-08"
        ixz="-6.5995E-08"
        iyy="0.00082121"
        iyz="-1.3406E-08"
        izz="0.00092531" />
    </inertial>
    <visual>
      <origin
        xyz="0 0 0"
        rpy="0 0 0" />
      <geometry>
        <mesh
          filename="package://nz/meshes/right_calf_Link.STL" />
      </geometry>
      <material
        name="">
        <color
          rgba="0.79216 0.81961 0.93333 1" />
      </material>
    </visual>
    <collision>
      <origin
        xyz="0 0 0"
        rpy="0 0 0" />
      <geometry>
        <mesh
          filename="package://nz/meshes/right_calf_Link.STL" />
      </geometry>
    </collision>
  </link>
  <joint
    name="right_calf_joint"
    type="continuous">
    <origin
      xyz="0.18 0 -0.018"
      rpy="0 0 -2.3479" />
    <parent
      link="right_thigh_Link" />
    <child
      link="right_calf_Link" />
    <axis
      xyz="0 0 1" />
    <limit
      lower="0"
      upper="1.3963"
      effort="40"
      velocity="0" />
  </joint>
  <link
    name="right_wheel_Link">
    <inertial>
      <origin
        xyz="-2.94902990916057E-13 3.30200866649477E-11 -0.0134999704617842"
        rpy="0 0 0" />
      <mass
        value="0.440514867448174" />
      <inertia
        ixx="0.00089136843602796"
        ixy="1.88104758488178E-12"
        ixz="2.34574152544279E-15"
        iyy="0.00089136845240295"
        iyz="-2.67712919849213E-13"
        izz="0.00165284876799872" />
    </inertial>
    <visual>
      <origin
        xyz="0 0 0"
        rpy="0 0 0" />
      <geometry>
        <mesh
          filename="package://nz/meshes/right_wheel_Link.STL" />
      </geometry>
      <material
        name="">
        <color
          rgba="0.376470588235294 0.376470588235294 0.376470588235294 1" />
      </material>
    </visual>
    <collision>
      <origin
        xyz="0 0 0"
        rpy="0 0 0" />
      <geometry>
        <mesh
          filename="package://nz/meshes/right_wheel_Link.STL" />
      </geometry>
    </collision>
  </link>
  <joint
    name="right_wheel_joint"
    type="continuous">
    <origin
      xyz="0.216 0 -0.027"
      rpy="0 0 -1.5708" />
    <parent
      link="right_calf_Link" />
    <child
      link="right_wheel_Link" />
    <axis
      xyz="0 0 1" />
    <limit
      effort="12"
      velocity="0" />
  </joint>
</robot>